Workbook

Sheet Start Here
A1: Payday Super review: s 18C deadlines and the SG charge estimate
A3: 1. On Register, paste one contribution line per row over the example rows, in the eleven canonical columns the command line tool reads and the importer writes. Dates are real Excel dates; amounts are dollars; yes/no columns take yes, no or blank (no).
A4: 2. On Summary, set the as-at date (notional earnings on unpaid lines run to it), an assessment date if the ATO has assessed, and the two confirmations the command line tool asks for: LCR 2026/1 transition allocation and remittance-only review.
A5: 3. Read the calculated columns on Register: pathway, final deadline, verdict (ON_TIME, AT_RISK, LATE, UNPAID, UNKNOWN, SKIPPED), the conservative outer outcomes where the facts cannot decide, days late, final shortfall after s 18D, notional earnings, the uplift range and the experimental SG charge estimate range.
A6: 4. Review Checks: BLOCKED means the register cannot be read or a required confirmation is missing. REVIEW means a line is exposed, a line is undecided, or the file cannot produce ON_TIME and remittance-only review is not confirmed. PASS mirrors the command line tool's exit code 0.
A7: 5. The statutory test is receipt by the fund. A remittance date alone gives AT_RISK, never ON_TIME. Fill fund_received_date from the clearing house or fund before treating a verdict as final.
A8: 6. Experimental review aid. Not a compliance determination. The ATO makes the assessment; choice loading, the maximum contributions base and post-assessment charges are not estimated.
A10: Overall status
A11: ='Review Checks'!B13 -> REVIEW
A13: payday-super-checker workbook, engine 0.1.3. Macro-free. Not advice; see DISCLAIMER.md in the repository.

Sheet Register
A1: employee_id | B1: payment_date | C1: sg_amount | D1: remitted_date | E1: remitted_amount | F1: matched_amount | G1: fund_received_date | H1: first_contribution_to_fund | I1: out_of_cycle | J1: next_standard_payday | K1: defined_benefit | L1: Flag_db | M1: Flag_ooc | N1: Flag_ftf | O1: Row_problem | P1: Guard | Q1: Cap | R1: Due_ooc | S1: Due_ftf | T1: Own_due | U1: Own_pathway | V1: Earliest_prepay | W1: Settled | X1: Remit | Y1: Receipt_credit | Z1: Credit | AA1: Evidence_own | AB1: Confirmed_latest | AC1: Possible_latest | AD1: Final_due | AE1: Pathway | AF1: Possible_item4 | AG1: Past_horizon | AH1: Branch | AI1: Verdict | AJ1: Unassessable_between | AK1: Exposed | AL1: Stale_prepay | AM1: OTRC | AN1: Base_shortfall | AO1: Offset_s18D | AP1: Final_shortfall | AQ1: Lateness_basis | AR1: Outstanding_to | AS1: NEC_end | AT1: Days_late | AU1: NEC | AV1: GIC_estimated | AW1: Shortfall_r | AX1: NEC_r | AY1: Uplift_best | AZ1: Uplift_worst | BA1: SGC_low | BB1: SGC_high | BC1: Transition_row | BD1: Receipt_established | BE1: Assessable | BF1: Duplicate
A2: EMP001 | B2: 46212 | C2: 612 | D2: 46217 | G2: 46219 | H2: no | I2: no | K2: no | L2: =IF(OR(LOWER(TRIM(tblLines[[#This Row],[defined_benefit]]&""))={"1","t","true","y","yes"}),1,IF(OR(LOWER(TRIM(tblLines[[#This Row],[defined_benefit]]&""))={"","0","f","false","n","no"}),0,"")) -> 0 | M2: =IF(OR(LOWER(TRIM(tblLines[[#This Row],[out_of_cycle]]&""))={"1","t","true","y","yes"}),1,IF(OR(LOWER(TRIM(tblLines[[#This Row],[out_of_cycle]]&""))={"","0","f","false","n","no"}),0,"")) -> 0 | N2: =IF(OR(LOWER(TRIM(tblLines[[#This Row],[first_contribution_to_fund]]&""))={"1","t","true","y","yes"}),1,IF(OR(LOWER(TRIM(tblLines[[#This Row],[first_contribution_to_fund]]&""))={"","0","f","false","n","no"}),0,"")) -> 0 | O2: =TRIM(IF(OR(AND(tblLines[[#This Row],[payment_date]]<>"",NOT(ISNUMBER(tblLines[[#This Row],[payment_date]]))),AND(tblLines[[#This Row],[remitted_date]]<>"",NOT(ISNUMBER(tblLines[[#This Row],[remitted_date]]))),AND(tblLines[[#This Row],[fund_received_date]]<>"",NOT(ISNUMBER(tblLines[[#This Row],[fund_received_date]]))),AND(tblLines[[#This Row],[next_standard_payday]]<>"",NOT(ISNUMBER(tblLines[[#This Row],[next_standard_payday]])))),"date ","")&IF(NOT(ISNUMBER(tblLines[[#This Row],[payment_date]])),"payment_date ","")&IF(AND(ISNUMBER(tblLines[[#This Row],[payment_date]]),tblLines[[#This Row],[payment_date]]<DATE(2026,7,1)),"pre-1-Jul-2026 ","")&IF(OR(AND(tblLines[[#This Row],[sg_amount]]<>"",OR(NOT(ISNUMBER(tblLines[[#This Row],[sg_amount]])),tblLines[[#This Row],[sg_amount]]<0)),AND(tblLines[[#This Row],[remitted_amount]]<>"",OR(NOT(ISNUMBER(tblLines[[#This Row],[remitted_amount]])),tblLines[[#This Row],[remitted_amount]]<0)),AND(tblLines[[#This Row],[matched_amount]]<>"",OR(NOT(ISNUMBER(tblLines[[#This Row],[matched_amount]])),tblLines[[#This Row],[matched_amount]]<0))),"amount ","")&IF(NOT(ISNUMBER(tblLines[[#This Row],[sg_amount]])),"sg_amount ","")&IF(OR(tblLines[[#This Row],[Flag_ftf]]="",tblLines[[#This Row],[Flag_ooc]]="",tblLines[[#This Row],[Flag_db]]=""),"yes/no ","")&IF(AND(ISNUMBER(tblLines[[#This Row],[remitted_amount]]),ISNUMBER(tblLines[[#This Row],[sg_amount]]),tblLines[[#This Row],[remitted_amount]]>tblLines[[#This Row],[sg_amount]]),"remitted_amount>sg ","")&IF(AND(ISNUMBER(tblLines[[#This Row],[remitted_amount]]),NOT(ISNUMBER(tblLines[[#This Row],[remitted_date]]))),"remitted_amount-needs-date ","")&IF(AND(ISNUMBER(tblLines[[#This Row],[matched_amount]]),ISNUMBER(tblLines[[#This Row],[sg_amount]]),tblLines[[#This Row],[matched_amount]]>tblLines[[#This Row],[sg_amount]]),"matched_amount>sg ","")&IF(AND(ISNUMBER(tblLines[[#This Row],[matched_amount]]),ISNUMBER(tblLines[[#This Row],[remitted_amount]]),tblLines[[#This Row],[remitted_amount]]>tblLines[[#This Row],[matched_amount]]),"remitted_amount>matched ","")&IF(AND(ISNUMBER(tblLines[[#This Row],[matched_amount]]),ISNUMBER(tblLines[[#This Row],[sg_amount]]),tblLines[[#This Row],[matched_amount]]<tblLines[[#This Row],[sg_amount]],ISNUMBER(tblLines[[#This Row],[remitted_date]]),NOT(ISNUMBER(tblLines[[#This Row],[remitted_amount]]))),"partial-match-needs-remitted_amount ","")&IF(AND(ISNUMBER(tblLines[[#This Row],[fund_received_date]]),ISNUMBER(tblLines[[#This Row],[remitted_date]]),tblLines[[#This Row],[fund_received_date]]<tblLines[[#This Row],[remitted_date]]),"receipt-before-remittance ","")&IF(AND(tblLines[[#This Row],[Flag_ooc]]=1,NOT(ISNUMBER(tblLines[[#This Row],[next_standard_payday]]))),"out_of_cycle-needs-next_standard_payday ","")&IF(AND(tblLines[[#This Row],[Flag_ooc]]=1,ISNUMBER(tblLines[[#This Row],[next_standard_payday]]),ISNUMBER(tblLines[[#This Row],[payment_date]]),tblLines[[#This Row],[next_standard_payday]]<=tblLines[[#This Row],[payment_date]]),"next_standard_payday-not-after-payday ","")) | P2: =IF(OR(_xlfn.ISFORMULA(tblLines[[#This Row],[employee_id]]),_xlfn.ISFORMULA(tblLines[[#This Row],[payment_date]]),_xlfn.ISFORMULA(tblLines[[#This Row],[sg_amount]]),_xlfn.ISFORMULA(tblLines[[#This Row],[remitted_date]]),_xlfn.ISFORMULA(tblLines[[#This Row],[remitted_amount]]),_xlfn.ISFORMULA(tblLines[[#This Row],[matched_amount]]),_xlfn.ISFORMULA(tblLines[[#This Row],[fund_received_date]]),_xlfn.ISFORMULA(tblLines[[#This Row],[first_contribution_to_fund]]),_xlfn.ISFORMULA(tblLines[[#This Row],[out_of_cycle]]),_xlfn.ISFORMULA(tblLines[[#This Row],[next_standard_payday]]),_xlfn.ISFORMULA(tblLines[[#This Row],[defined_benefit]])),1,0) -> 0 | Q2: =IF(ISNUMBER(tblLines[[#This Row],[matched_amount]]),tblLines[[#This Row],[matched_amount]],IF(ISNUMBER(tblLines[[#This Row],[remitted_amount]]),tblLines[[#This Row],[remitted_amount]],tblLines[[#This Row],[sg_amount]])) -> 612 | R2: =IF(AND(tblLines[[#This Row],[Flag_ooc]]=1,ISNUMBER(tblLines[[#This Row],[next_standard_payday]])),WORKDAY.INTL(tblLines[[#This Row],[next_standard_payday]],7,1,tblHolidays[date]),"") | S2: =IF(tblLines[[#This Row],[Flag_ftf]]=1,WORKDAY.INTL(tblLines[[#This Row],[payment_date]],20,1,tblHolidays[date]),"") | T2: =IF(OR(tblLines[[#This Row],[Flag_db]]=1,NOT(ISNUMBER(tblLines[[#This Row],[payment_date]]))),"",IF(OR(tblLines[[#This Row],[Flag_ooc]]=1,tblLines[[#This Row],[Flag_ftf]]=1),MAX(tblLines[[#This Row],[Due_ooc]],tblLines[[#This Row],[Due_ftf]]),WORKDAY.INTL(tblLines[[#This Row],[payment_date]],7,1,tblHolidays[date]))) -> 46223 | U2: =IF(tblLines[[#This Row],[Flag_db]]=1,"SKIP_DB",IF(tblLines[[#This Row],[Flag_ooc]]=1,IF(AND(tblLines[[#This Row],[Flag_ftf]]=1,tblLines[[#This Row],[Due_ftf]]>tblLines[[#This Row],[Due_ooc]]),"EXTENDED_20BD","OUT_OF_CYCLE"),IF(tblLines[[#This Row],[Flag_ftf]]=1,"EXTENDED_20BD","USUAL_7BD"))) -> USUAL_7BD | V2: =IF(ISNUMBER(tblLines[[#This Row],[payment_date]]),EDATE(tblLines[[#This Row],[payment_date]]-1,-12)+1,"") -> 45847 | W2: =IF(AND(ISNUMBER(tblLines[[#This Row],[fund_received_date]]),tblLines[[#This Row],[fund_received_date]]<=Summary!$B$2),tblLines[[#This Row],[fund_received_date]],"") -> 46219 | X2: =IF(AND(ISNUMBER(tblLines[[#This Row],[remitted_date]]),tblLines[[#This Row],[remitted_date]]<=Summary!$B$2),tblLines[[#This Row],[remitted_date]],"") -> 46217 | Y2: =IF(tblLines[[#This Row],[Settled]]<>"",MIN(ROUND(tblLines[[#This Row],[Cap]],2),ROUND(tblLines[[#This Row],[sg_amount]],2)),0) -> 612 | Z2: =IF(ISNUMBER(tblLines[[#This Row],[remitted_amount]]),IF(tblLines[[#This Row],[Remit]]<>"",MIN(ROUND(tblLines[[#This Row],[remitted_amount]],2),ROUND(tblLines[[#This Row],[sg_amount]],2)),0),IF(tblLines[[#This Row],[Remit]]<>"",ROUND(tblLines[[#This Row],[sg_amount]],2),0)) -> 612 | AA2: =IF(OR(tblLines[[#This Row],[Own_due]]="",tblLines[[#This Row],[sg_amount]]<=0,tblLines[[#This Row],[Flag_db]]=1,tblLines[[#This Row],[Cap]]<=0),"impossible",IF(ISNUMBER(tblLines[[#This Row],[fund_received_date]]),IF(tblLines[[#This Row],[fund_received_date]]<tblLines[[#This Row],[Earliest_prepay]],"impossible",IF(tblLines[[#This Row],[fund_received_date]]<=Summary!$B$2,IF(OR(tblLines[[#This Row],[fund_received_date]]<tblLines[[#This Row],[payment_date]],tblLines[[#This Row],[fund_received_date]]<=tblLines[[#This Row],[Own_due]]),"confirmed",IF(tblLines[[#This Row],[fund_received_date]]>tblLines[[#This Row],[Own_due]],"impossible","possible")),IF(tblLines[[#This Row],[fund_received_date]]<=tblLines[[#This Row],[Own_due]],"possible","impossible"))),IF(AND(ISNUMBER(tblLines[[#This Row],[remitted_date]]),tblLines[[#This Row],[remitted_date]]>tblLines[[#This Row],[Own_due]]),"impossible","possible"))) -> confirmed | AB2: =IF(OR(tblLines[[#This Row],[Flag_db]]=1,tblLines[[#This Row],[Own_due]]=""),"",_xlfn.MAXIFS(tblLines[Own_due],tblLines[employee_id],tblLines[[#This Row],[employee_id]],tblLines[payment_date],"<"&tblLines[[#This Row],[payment_date]],tblLines[Evidence_own],"confirmed")) -> 0 | AC2: =IF(OR(tblLines[[#This Row],[Flag_db]]=1,tblLines[[#This Row],[Own_due]]=""),"",_xlfn.MAXIFS(tblLines[Own_due],tblLines[employee_id],tblLines[[#This Row],[employee_id]],tblLines[payment_date],"<"&tblLines[[#This Row],[payment_date]],tblLines[Evidence_own],"<>impossible")) -> 0 | AD2: =IF(tblLines[[#This Row],[Own_due]]="","",IF(AND(ISNUMBER(tblLines[[#This Row],[Confirmed_latest]]),tblLines[[#This Row],[Confirmed_latest]]>tblLines[[#This Row],[Own_due]]),tblLines[[#This Row],[Confirmed_latest]],tblLines[[#This Row],[Own_due]])) -> 46223 | AE2: =IF(tblLines[[#This Row],[Own_due]]="",tblLines[[#This Row],[Own_pathway]],IF(AND(ISNUMBER(tblLines[[#This Row],[Confirmed_latest]]),tblLines[[#This Row],[Confirmed_latest]]>tblLines[[#This Row],[Own_due]]),"ITEM4_ALIGNED",tblLines[[#This Row],[Own_pathway]])) -> USUAL_7BD | AF2: =IF(tblLines[[#This Row],[Final_due]]="","",IF(AND(ISNUMBER(tblLines[[#This Row],[Possible_latest]]),tblLines[[#This Row],[Possible_latest]]>tblLines[[#This Row],[Final_due]]),tblLines[[#This Row],[Possible_latest]],"")) | AG2: =IF(tblLines[[#This Row],[Final_due]]="","",IF((tblLines[[#This Row],[Final_due]]>Summary!$B$6),1,0)) -> 0 | AH2: =IF(tblLines[[#This Row],[Flag_db]]=1,"DB",IF(tblLines[[#This Row],[Final_due]]="","",IF(tblLines[[#This Row],[sg_amount]]<=0,"NIL",IF(tblLines[[#This Row],[Settled]]<>"",IF(tblLines[[#This Row],[Settled]]<tblLines[[#This Row],[payment_date]],IF(tblLines[[#This Row],[Settled]]>=tblLines[[#This Row],[Earliest_prepay]],IF((tblLines[[#This Row],[Receipt_credit]]>=tblLines[[#This Row],[sg_amount]]),"A1",IF(tblLines[[#This Row],[Final_due]]>=Summary!$B$2,"A2",IF(OR((tblLines[[#This Row],[Final_due]]>Summary!$B$6),AND((tblLines[[#This Row],[Possible_item4]]<>""),Summary!$B$2<=tblLines[[#This Row],[Possible_item4]])),"A3","A4"))),IF(tblLines[[#This Row],[Final_due]]>=Summary!$B$2,"S1",IF(OR((tblLines[[#This Row],[Final_due]]>Summary!$B$6),AND((tblLines[[#This Row],[Possible_item4]]<>""),Summary!$B$2<=tblLines[[#This Row],[Possible_item4]])),"S2","S3"))),IF(AND((tblLines[[#This Row],[Possible_item4]]<>""),tblLines[[#This Row],[Final_due]]<tblLines[[#This Row],[Settled]],tblLines[[#This Row],[Settled]]<=tblLines[[#This Row],[Possible_item4]]),IF((tblLines[[#This Row],[Receipt_credit]]>=tblLines[[#This Row],[sg_amount]]),"B1",IF(Summary!$B$2<=tblLines[[#This Row],[Possible_item4]],"B2","B3")),IF(AND((tblLines[[#This Row],[Final_due]]>Summary!$B$6),tblLines[[#This Row],[Settled]]>tblLines[[#This Row],[Final_due]]),IF((tblLines[[#This Row],[Receipt_credit]]>=tblLines[[#This Row],[sg_amount]]),"C1","C2"),IF(tblLines[[#This Row],[Settled]]<=tblLines[[#This Row],[Final_due]],IF((tblLines[[#This Row],[Receipt_credit]]>=tblLines[[#This Row],[sg_amount]]),"D1",IF(OR((tblLines[[#This Row],[Final_due]]>Summary!$B$6),AND((tblLines[[#This Row],[Possible_item4]]<>""),Summary!$B$2<=tblLines[[#This Row],[Possible_item4]])),"D2",IF(tblLines[[#This Row],[Final_due]]<Summary!$B$2,"D3","D4"))),"E")))),IF(AND(tblLines[[#This Row],[Remit]]<>"",tblLines[[#This Row],[sg_amount]]-tblLines[[#This Row],[Credit]]<=0),IF(AND((tblLines[[#This Row],[Possible_item4]]<>""),tblLines[[#This Row],[Final_due]]<tblLines[[#This Row],[Remit]],tblLines[[#This Row],[Remit]]<=tblLines[[#This Row],[Possible_item4]]),"R1",IF(AND((tblLines[[#This Row],[Final_due]]>Summary!$B$6),tblLines[[#This Row],[Remit]]>tblLines[[#This Row],[Final_due]]),"R2",IF(tblLines[[#This Row],[Remit]]<=tblLines[[#This Row],[Final_due]],"R3","R4"))),IF(tblLines[[#This Row],[Final_due]]<Summary!$B$2,IF(OR((tblLines[[#This Row],[Final_due]]>Summary!$B$6),AND((tblLines[[#This Row],[Possible_item4]]<>""),Summary!$B$2<=tblLines[[#This Row],[Possible_item4]])),"N1","N2"),"N3")))))) -> D1 | AI2: =IF(tblLines[[#This Row],[Branch]]="","",INDEX(tblCodes[verdict],MATCH(tblLines[[#This Row],[Branch]],tblCodes[code],0))) -> ON_TIME | AJ2: =IF(tblLines[[#This Row],[Branch]]="","",T(INDEX(tblCodes[unassessable],MATCH(tblLines[[#This Row],[Branch]],tblCodes[code],0)))) | AK2: =IF(tblLines[[#This Row],[Branch]]="",0,INDEX(tblCodes[exposed],MATCH(tblLines[[#This Row],[Branch]],tblCodes[code],0))) -> 0 | AL2: =IF(tblLines[[#This Row],[Branch]]="",0,INDEX(tblCodes[stale],MATCH(tblLines[[#This Row],[Branch]],tblCodes[code],0))) -> 0 | AM2: =IF(tblLines[[#This Row],[Branch]]="",0,INDEX(tblCodes[otrc],MATCH(tblLines[[#This Row],[Branch]],tblCodes[code],0))*tblLines[[#This Row],[Receipt_credit]]) -> 612 | AN2: =IF((tblLines[[#This Row],[Exposed]]=1),MAX(ROUND(tblLines[[#This Row],[sg_amount]],2)-tblLines[[#This Row],[OTRC]],0),"") | AO2: =IF((tblLines[[#This Row],[Exposed]]=1),IF(AND(tblLines[[#This Row],[Settled]]<>"",tblLines[[#This Row],[Stale_prepay]]=0,tblLines[[#This Row],[Settled]]>tblLines[[#This Row],[Final_due]],OR(Summary!$B$3="",tblLines[[#This Row],[Settled]]<Summary!$B$3)),MIN(tblLines[[#This Row],[Receipt_credit]],tblLines[[#This Row],[Base_shortfall]]),0),"") | AP2: =IF((tblLines[[#This Row],[Exposed]]=1),MAX(tblLines[[#This Row],[Base_shortfall]]-tblLines[[#This Row],[Offset_s18D]],0),"") | AQ2: =IF((tblLines[[#This Row],[Exposed]]=1),IF(AND(tblLines[[#This Row],[Settled]]<>"",tblLines[[#This Row],[Stale_prepay]]=0,(tblLines[[#This Row],[Receipt_credit]]>=tblLines[[#This Row],[sg_amount]])),"fund receipt",IF(AND(tblLines[[#This Row],[Settled]]<>"",tblLines[[#This Row],[Stale_prepay]]=0),"as-at date (shortfall remains after part receipt)",IF(AND(OR(tblLines[[#This Row],[Settled]]<>"",tblLines[[#This Row],[Remit]]<>""),tblLines[[#This Row],[Stale_prepay]]=0),"as-at date (no fund receipt recorded)","as-at date (nothing applied to this payday)"))),"") | AR2: =IF((tblLines[[#This Row],[Exposed]]=1),IF(AND(tblLines[[#This Row],[Settled]]<>"",tblLines[[#This Row],[Stale_prepay]]=0,(tblLines[[#This Row],[Receipt_credit]]>=tblLines[[#This Row],[sg_amount]])),tblLines[[#This Row],[Settled]],Summary!$B$2),"") | AS2: =IF((tblLines[[#This Row],[Exposed]]=1),MIN(IF(Summary!$B$3="",DATE(2030,12,31),Summary!$B$3-1),IF(AND(tblLines[[#This Row],[Settled]]<>"",tblLines[[#This Row],[Stale_prepay]]=0,(tblLines[[#This Row],[Receipt_credit]]>=tblLines[[#This Row],[sg_amount]]),tblLines[[#This Row],[Final_shortfall]]=0),tblLines[[#This Row],[Settled]],Summary!$B$2)),"") | AT2: =IF((tblLines[[#This Row],[Exposed]]=1),IF(tblLines[[#This Row],[Past_horizon]]=1,"",MAX(tblLines[[#This Row],[Outstanding_to]]-tblLines[[#This Row],[Final_due]],0)),"") | AU2: =IF((tblLines[[#This Row],[Exposed]]=1),IF(tblLines[[#This Row],[NEC_end]]>tblLines[[#This Row],[Final_due]],tblLines[[#This Row],[Base_shortfall]]*(EXP(SUMPRODUCT((((((tblLines[[#This Row],[NEC_end]]+tblGic[to]-ABS(tblLines[[#This Row],[NEC_end]]-tblGic[to]))/2)-(((tblLines[[#This Row],[Final_due]]+1)+tblGic[from]+ABS((tblLines[[#This Row],[Final_due]]+1)-tblGic[from]))/2)+1)>0)*(((tblLines[[#This Row],[NEC_end]]+tblGic[to]-ABS(tblLines[[#This Row],[NEC_end]]-tblGic[to]))/2)-(((tblLines[[#This Row],[Final_due]]+1)+tblGic[from]+ABS((tblLines[[#This Row],[Final_due]]+1)-tblGic[from]))/2)+1))*LN(1+tblGic[annual_pct]/100/tblGic[divisor])))-1),0),"") | AV2: =IF((tblLines[[#This Row],[Exposed]]=1),IF(tblLines[[#This Row],[NEC_end]]>Summary!$B$7,1,0),"") | AW2: =IF((tblLines[[#This Row],[Exposed]]=1),ROUND(tblLines[[#This Row],[Final_shortfall]],2),"") | AX2: =IF((tblLines[[#This Row],[Exposed]]=1),ROUND(tblLines[[#This Row],[NEC]],2),"") | AY2: =IF((tblLines[[#This Row],[Exposed]]=1),0,"") | AZ2: =IF((tblLines[[#This Row],[Exposed]]=1),ROUND(0.6*(tblLines[[#This Row],[Final_shortfall]]+tblLines[[#This Row],[NEC]]),2),"") | BA2: =IF((tblLines[[#This Row],[Exposed]]=1),tblLines[[#This Row],[Shortfall_r]]+tblLines[[#This Row],[NEC_r]]+tblLines[[#This Row],[Uplift_best]],"") | BB2: =IF((tblLines[[#This Row],[Exposed]]=1),tblLines[[#This Row],[Shortfall_r]]+tblLines[[#This Row],[NEC_r]]+tblLines[[#This Row],[Uplift_worst]],"") | BC2: =IF(AND(tblLines[[#This Row],[Flag_db]]<>1,ISNUMBER(tblLines[[#This Row],[sg_amount]]),tblLines[[#This Row],[sg_amount]]>0,tblLines[[#This Row],[Cap]]>0,OR(ISNUMBER(tblLines[[#This Row],[fund_received_date]]),ISNUMBER(tblLines[[#This Row],[remitted_date]])),IF(ISNUMBER(tblLines[[#This Row],[fund_received_date]]),tblLines[[#This Row],[fund_received_date]],tblLines[[#This Row],[remitted_date]])<=DATE(2026,7,28)),1,0) -> 1 | BD2: =IF(tblLines[[#This Row],[Settled]]<>"",1,0) -> 1 | BE2: =IF(AND(tblLines[[#This Row],[Verdict]]<>"",tblLines[[#This Row],[Verdict]]<>"SKIPPED",ISNUMBER(tblLines[[#This Row],[sg_amount]]),tblLines[[#This Row],[sg_amount]]>0),1,0) -> 1 | BF2: =IF(COUNTIFS(tblLines[employee_id],tblLines[[#This Row],[employee_id]],tblLines[payment_date],tblLines[[#This Row],[payment_date]],tblLines[sg_amount],tblLines[[#This Row],[sg_amount]],tblLines[remitted_date],tblLines[[#This Row],[remitted_date]]&"",tblLines[fund_received_date],tblLines[[#This Row],[fund_received_date]]&"")>1,1,0) -> 0
A3: EMP002 | B3: 46212 | C3: 540 | D3: 46233 | G3: 46238 | H3: no | I3: no | K3: no | L3: =IF(OR(LOWER(TRIM(tblLines[[#This Row],[defined_benefit]]&""))={"1","t","true","y","yes"}),1,IF(OR(LOWER(TRIM(tblLines[[#This Row],[defined_benefit]]&""))={"","0","f","false","n","no"}),0,"")) -> 0 | M3: =IF(OR(LOWER(TRIM(tblLines[[#This Row],[out_of_cycle]]&""))={"1","t","true","y","yes"}),1,IF(OR(LOWER(TRIM(tblLines[[#This Row],[out_of_cycle]]&""))={"","0","f","false","n","no"}),0,"")) -> 0 | N3: =IF(OR(LOWER(TRIM(tblLines[[#This Row],[first_contribution_to_fund]]&""))={"1","t","true","y","yes"}),1,IF(OR(LOWER(TRIM(tblLines[[#This Row],[first_contribution_to_fund]]&""))={"","0","f","false","n","no"}),0,"")) -> 0 | O3: =TRIM(IF(OR(AND(tblLines[[#This Row],[payment_date]]<>"",NOT(ISNUMBER(tblLines[[#This Row],[payment_date]]))),AND(tblLines[[#This Row],[remitted_date]]<>"",NOT(ISNUMBER(tblLines[[#This Row],[remitted_date]]))),AND(tblLines[[#This Row],[fund_received_date]]<>"",NOT(ISNUMBER(tblLines[[#This Row],[fund_received_date]]))),AND(tblLines[[#This Row],[next_standard_payday]]<>"",NOT(ISNUMBER(tblLines[[#This Row],[next_standard_payday]])))),"date ","")&IF(NOT(ISNUMBER(tblLines[[#This Row],[payment_date]])),"payment_date ","")&IF(AND(ISNUMBER(tblLines[[#This Row],[payment_date]]),tblLines[[#This Row],[payment_date]]<DATE(2026,7,1)),"pre-1-Jul-2026 ","")&IF(OR(AND(tblLines[[#This Row],[sg_amount]]<>"",OR(NOT(ISNUMBER(tblLines[[#This Row],[sg_amount]])),tblLines[[#This Row],[sg_amount]]<0)),AND(tblLines[[#This Row],[remitted_amount]]<>"",OR(NOT(ISNUMBER(tblLines[[#This Row],[remitted_amount]])),tblLines[[#This Row],[remitted_amount]]<0)),AND(tblLines[[#This Row],[matched_amount]]<>"",OR(NOT(ISNUMBER(tblLines[[#This Row],[matched_amount]])),tblLines[[#This Row],[matched_amount]]<0))),"amount ","")&IF(NOT(ISNUMBER(tblLines[[#This Row],[sg_amount]])),"sg_amount ","")&IF(OR(tblLines[[#This Row],[Flag_ftf]]="",tblLines[[#This Row],[Flag_ooc]]="",tblLines[[#This Row],[Flag_db]]=""),"yes/no ","")&IF(AND(ISNUMBER(tblLines[[#This Row],[remitted_amount]]),ISNUMBER(tblLines[[#This Row],[sg_amount]]),tblLines[[#This Row],[remitted_amount]]>tblLines[[#This Row],[sg_amount]]),"remitted_amount>sg ","")&IF(AND(ISNUMBER(tblLines[[#This Row],[remitted_amount]]),NOT(ISNUMBER(tblLines[[#This Row],[remitted_date]]))),"remitted_amount-needs-date ","")&IF(AND(ISNUMBER(tblLines[[#This Row],[matched_amount]]),ISNUMBER(tblLines[[#This Row],[sg_amount]]),tblLines[[#This Row],[matched_amount]]>tblLines[[#This Row],[sg_amount]]),"matched_amount>sg ","")&IF(AND(ISNUMBER(tblLines[[#This Row],[matched_amount]]),ISNUMBER(tblLines[[#This Row],[remitted_amount]]),tblLines[[#This Row],[remitted_amount]]>tblLines[[#This Row],[matched_amount]]),"remitted_amount>matched ","")&IF(AND(ISNUMBER(tblLines[[#This Row],[matched_amount]]),ISNUMBER(tblLines[[#This Row],[sg_amount]]),tblLines[[#This Row],[matched_amount]]<tblLines[[#This Row],[sg_amount]],ISNUMBER(tblLines[[#This Row],[remitted_date]]),NOT(ISNUMBER(tblLines[[#This Row],[remitted_amount]]))),"partial-match-needs-remitted_amount ","")&IF(AND(ISNUMBER(tblLines[[#This Row],[fund_received_date]]),ISNUMBER(tblLines[[#This Row],[remitted_date]]),tblLines[[#This Row],[fund_received_date]]<tblLines[[#This Row],[remitted_date]]),"receipt-before-remittance ","")&IF(AND(tblLines[[#This Row],[Flag_ooc]]=1,NOT(ISNUMBER(tblLines[[#This Row],[next_standard_payday]]))),"out_of_cycle-needs-next_standard_payday ","")&IF(AND(tblLines[[#This Row],[Flag_ooc]]=1,ISNUMBER(tblLines[[#This Row],[next_standard_payday]]),ISNUMBER(tblLines[[#This Row],[payment_date]]),tblLines[[#This Row],[next_standard_payday]]<=tblLines[[#This Row],[payment_date]]),"next_standard_payday-not-after-payday ","")) | P3: =IF(OR(_xlfn.ISFORMULA(tblLines[[#This Row],[employee_id]]),_xlfn.ISFORMULA(tblLines[[#This Row],[payment_date]]),_xlfn.ISFORMULA(tblLines[[#This Row],[sg_amount]]),_xlfn.ISFORMULA(tblLines[[#This Row],[remitted_date]]),_xlfn.ISFORMULA(tblLines[[#This Row],[remitted_amount]]),_xlfn.ISFORMULA(tblLines[[#This Row],[matched_amount]]),_xlfn.ISFORMULA(tblLines[[#This Row],[fund_received_date]]),_xlfn.ISFORMULA(tblLines[[#This Row],[first_contribution_to_fund]]),_xlfn.ISFORMULA(tblLines[[#This Row],[out_of_cycle]]),_xlfn.ISFORMULA(tblLines[[#This Row],[next_standard_payday]]),_xlfn.ISFORMULA(tblLines[[#This Row],[defined_benefit]])),1,0) -> 0 | Q3: =IF(ISNUMBER(tblLines[[#This Row],[matched_amount]]),tblLines[[#This Row],[matched_amount]],IF(ISNUMBER(tblLines[[#This Row],[remitted_amount]]),tblLines[[#This Row],[remitted_amount]],tblLines[[#This Row],[sg_amount]])) -> 540 | R3: =IF(AND(tblLines[[#This Row],[Flag_ooc]]=1,ISNUMBER(tblLines[[#This Row],[next_standard_payday]])),WORKDAY.INTL(tblLines[[#This Row],[next_standard_payday]],7,1,tblHolidays[date]),"") | S3: =IF(tblLines[[#This Row],[Flag_ftf]]=1,WORKDAY.INTL(tblLines[[#This Row],[payment_date]],20,1,tblHolidays[date]),"") | T3: =IF(OR(tblLines[[#This Row],[Flag_db]]=1,NOT(ISNUMBER(tblLines[[#This Row],[payment_date]]))),"",IF(OR(tblLines[[#This Row],[Flag_ooc]]=1,tblLines[[#This Row],[Flag_ftf]]=1),MAX(tblLines[[#This Row],[Due_ooc]],tblLines[[#This Row],[Due_ftf]]),WORKDAY.INTL(tblLines[[#This Row],[payment_date]],7,1,tblHolidays[date]))) -> 46223 | U3: =IF(tblLines[[#This Row],[Flag_db]]=1,"SKIP_DB",IF(tblLines[[#This Row],[Flag_ooc]]=1,IF(AND(tblLines[[#This Row],[Flag_ftf]]=1,tblLines[[#This Row],[Due_ftf]]>tblLines[[#This Row],[Due_ooc]]),"EXTENDED_20BD","OUT_OF_CYCLE"),IF(tblLines[[#This Row],[Flag_ftf]]=1,"EXTENDED_20BD","USUAL_7BD"))) -> USUAL_7BD | V3: =IF(ISNUMBER(tblLines[[#This Row],[payment_date]]),EDATE(tblLines[[#This Row],[payment_date]]-1,-12)+1,"") -> 45847 | W3: =IF(AND(ISNUMBER(tblLines[[#This Row],[fund_received_date]]),tblLines[[#This Row],[fund_received_date]]<=Summary!$B$2),tblLines[[#This Row],[fund_received_date]],"") -> 46238 | X3: =IF(AND(ISNUMBER(tblLines[[#This Row],[remitted_date]]),tblLines[[#This Row],[remitted_date]]<=Summary!$B$2),tblLines[[#This Row],[remitted_date]],"") -> 46233 | Y3: =IF(tblLines[[#This Row],[Settled]]<>"",MIN(ROUND(tblLines[[#This Row],[Cap]],2),ROUND(tblLines[[#This Row],[sg_amount]],2)),0) -> 540 | Z3: =IF(ISNUMBER(tblLines[[#This Row],[remitted_amount]]),IF(tblLines[[#This Row],[Remit]]<>"",MIN(ROUND(tblLines[[#This Row],[remitted_amount]],2),ROUND(tblLines[[#This Row],[sg_amount]],2)),0),IF(tblLines[[#This Row],[Remit]]<>"",ROUND(tblLines[[#This Row],[sg_amount]],2),0)) -> 540 | AA3: =IF(OR(tblLines[[#This Row],[Own_due]]="",tblLines[[#This Row],[sg_amount]]<=0,tblLines[[#This Row],[Flag_db]]=1,tblLines[[#This Row],[Cap]]<=0),"impossible",IF(ISNUMBER(tblLines[[#This Row],[fund_received_date]]),IF(tblLines[[#This Row],[fund_received_date]]<tblLines[[#This Row],[Earliest_prepay]],"impossible",IF(tblLines[[#This Row],[fund_received_date]]<=Summary!$B$2,IF(OR(tblLines[[#This Row],[fund_received_date]]<tblLines[[#This Row],[payment_date]],tblLines[[#This Row],[fund_received_date]]<=tblLines[[#This Row],[Own_due]]),"confirmed",IF(tblLines[[#This Row],[fund_received_date]]>tblLines[[#This Row],[Own_due]],"impossible","possible")),IF(tblLines[[#This Row],[fund_received_date]]<=tblLines[[#This Row],[Own_due]],"possible","impossible"))),IF(AND(ISNUMBER(tblLines[[#This Row],[remitted_date]]),tblLines[[#This Row],[remitted_date]]>tblLines[[#This Row],[Own_due]]),"impossible","possible"))) -> impossible | AB3: =IF(OR(tblLines[[#This Row],[Flag_db]]=1,tblLines[[#This Row],[Own_due]]=""),"",_xlfn.MAXIFS(tblLines[Own_due],tblLines[employee_id],tblLines[[#This Row],[employee_id]],tblLines[payment_date],"<"&tblLines[[#This Row],[payment_date]],tblLines[Evidence_own],"confirmed")) -> 0 | AC3: =IF(OR(tblLines[[#This Row],[Flag_db]]=1,tblLines[[#This Row],[Own_due]]=""),"",_xlfn.MAXIFS(tblLines[Own_due],tblLines[employee_id],tblLines[[#This Row],[employee_id]],tblLines[payment_date],"<"&tblLines[[#This Row],[payment_date]],tblLines[Evidence_own],"<>impossible")) -> 0 | AD3: =IF(tblLines[[#This Row],[Own_due]]="","",IF(AND(ISNUMBER(tblLines[[#This Row],[Confirmed_latest]]),tblLines[[#This Row],[Confirmed_latest]]>tblLines[[#This Row],[Own_due]]),tblLines[[#This Row],[Confirmed_latest]],tblLines[[#This Row],[Own_due]])) -> 46223 | AE3: =IF(tblLines[[#This Row],[Own_due]]="",tblLines[[#This Row],[Own_pathway]],IF(AND(ISNUMBER(tblLines[[#This Row],[Confirmed_latest]]),tblLines[[#This Row],[Confirmed_latest]]>tblLines[[#This Row],[Own_due]]),"ITEM4_ALIGNED",tblLines[[#This Row],[Own_pathway]])) -> USUAL_7BD | AF3: =IF(tblLines[[#This Row],[Final_due]]="","",IF(AND(ISNUMBER(tblLines[[#This Row],[Possible_latest]]),tblLines[[#This Row],[Possible_latest]]>tblLines[[#This Row],[Final_due]]),tblLines[[#This Row],[Possible_latest]],"")) | AG3: =IF(tblLines[[#This Row],[Final_due]]="","",IF((tblLines[[#This Row],[Final_due]]>Summary!$B$6),1,0)) -> 0 | AH3: =IF(tblLines[[#This Row],[Flag_db]]=1,"DB",IF(tblLines[[#This Row],[Final_due]]="","",IF(tblLines[[#This Row],[sg_amount]]<=0,"NIL",IF(tblLines[[#This Row],[Settled]]<>"",IF(tblLines[[#This Row],[Settled]]<tblLines[[#This Row],[payment_date]],IF(tblLines[[#This Row],[Settled]]>=tblLines[[#This Row],[Earliest_prepay]],IF((tblLines[[#This Row],[Receipt_credit]]>=tblLines[[#This Row],[sg_amount]]),"A1",IF(tblLines[[#This Row],[Final_due]]>=Summary!$B$2,"A2",IF(OR((tblLines[[#This Row],[Final_due]]>Summary!$B$6),AND((tblLines[[#This Row],[Possible_item4]]<>""),Summary!$B$2<=tblLines[[#This Row],[Possible_item4]])),"A3","A4"))),IF(tblLines[[#This Row],[Final_due]]>=Summary!$B$2,"S1",IF(OR((tblLines[[#This Row],[Final_due]]>Summary!$B$6),AND((tblLines[[#This Row],[Possible_item4]]<>""),Summary!$B$2<=tblLines[[#This Row],[Possible_item4]])),"S2","S3"))),IF(AND((tblLines[[#This Row],[Possible_item4]]<>""),tblLines[[#This Row],[Final_due]]<tblLines[[#This Row],[Settled]],tblLines[[#This Row],[Settled]]<=tblLines[[#This Row],[Possible_item4]]),IF((tblLines[[#This Row],[Receipt_credit]]>=tblLines[[#This Row],[sg_amount]]),"B1",IF(Summary!$B$2<=tblLines[[#This Row],[Possible_item4]],"B2","B3")),IF(AND((tblLines[[#This Row],[Final_due]]>Summary!$B$6),tblLines[[#This Row],[Settled]]>tblLines[[#This Row],[Final_due]]),IF((tblLines[[#This Row],[Receipt_credit]]>=tblLines[[#This Row],[sg_amount]]),"C1","C2"),IF(tblLines[[#This Row],[Settled]]<=tblLines[[#This Row],[Final_due]],IF((tblLines[[#This Row],[Receipt_credit]]>=tblLines[[#This Row],[sg_amount]]),"D1",IF(OR((tblLines[[#This Row],[Final_due]]>Summary!$B$6),AND((tblLines[[#This Row],[Possible_item4]]<>""),Summary!$B$2<=tblLines[[#This Row],[Possible_item4]])),"D2",IF(tblLines[[#This Row],[Final_due]]<Summary!$B$2,"D3","D4"))),"E")))),IF(AND(tblLines[[#This Row],[Remit]]<>"",tblLines[[#This Row],[sg_amount]]-tblLines[[#This Row],[Credit]]<=0),IF(AND((tblLines[[#This Row],[Possible_item4]]<>""),tblLines[[#This Row],[Final_due]]<tblLines[[#This Row],[Remit]],tblLines[[#This Row],[Remit]]<=tblLines[[#This Row],[Possible_item4]]),"R1",IF(AND((tblLines[[#This Row],[Final_due]]>Summary!$B$6),tblLines[[#This Row],[Remit]]>tblLines[[#This Row],[Final_due]]),"R2",IF(tblLines[[#This Row],[Remit]]<=tblLines[[#This Row],[Final_due]],"R3","R4"))),IF(tblLines[[#This Row],[Final_due]]<Summary!$B$2,IF(OR((tblLines[[#This Row],[Final_due]]>Summary!$B$6),AND((tblLines[[#This Row],[Possible_item4]]<>""),Summary!$B$2<=tblLines[[#This Row],[Possible_item4]])),"N1","N2"),"N3")))))) -> E | AI3: =IF(tblLines[[#This Row],[Branch]]="","",INDEX(tblCodes[verdict],MATCH(tblLines[[#This Row],[Branch]],tblCodes[code],0))) -> LATE | AJ3: =IF(tblLines[[#This Row],[Branch]]="","",T(INDEX(tblCodes[unassessable],MATCH(tblLines[[#This Row],[Branch]],tblCodes[code],0)))) | AK3: =IF(tblLines[[#This Row],[Branch]]="",0,INDEX(tblCodes[exposed],MATCH(tblLines[[#This Row],[Branch]],tblCodes[code],0))) -> 1 | AL3: =IF(tblLines[[#This Row],[Branch]]="",0,INDEX(tblCodes[stale],MATCH(tblLines[[#This Row],[Branch]],tblCodes[code],0))) -> 0 | AM3: =IF(tblLines[[#This Row],[Branch]]="",0,INDEX(tblCodes[otrc],MATCH(tblLines[[#This Row],[Branch]],tblCodes[code],0))*tblLines[[#This Row],[Receipt_credit]]) -> 0 | AN3: =IF((tblLines[[#This Row],[Exposed]]=1),MAX(ROUND(tblLines[[#This Row],[sg_amount]],2)-tblLines[[#This Row],[OTRC]],0),"") -> 540 | AO3: =IF((tblLines[[#This Row],[Exposed]]=1),IF(AND(tblLines[[#This Row],[Settled]]<>"",tblLines[[#This Row],[Stale_prepay]]=0,tblLines[[#This Row],[Settled]]>tblLines[[#This Row],[Final_due]],OR(Summary!$B$3="",tblLines[[#This Row],[Settled]]<Summary!$B$3)),MIN(tblLines[[#This Row],[Receipt_credit]],tblLines[[#This Row],[Base_shortfall]]),0),"") -> 540 | AP3: =IF((tblLines[[#This Row],[Exposed]]=1),MAX(tblLines[[#This Row],[Base_shortfall]]-tblLines[[#This Row],[Offset_s18D]],0),"") -> 0 | AQ3: =IF((tblLines[[#This Row],[Exposed]]=1),IF(AND(tblLines[[#This Row],[Settled]]<>"",tblLines[[#This Row],[Stale_prepay]]=0,(tblLines[[#This Row],[Receipt_credit]]>=tblLines[[#This Row],[sg_amount]])),"fund receipt",IF(AND(tblLines[[#This Row],[Settled]]<>"",tblLines[[#This Row],[Stale_prepay]]=0),"as-at date (shortfall remains after part receipt)",IF(AND(OR(tblLines[[#This Row],[Settled]]<>"",tblLines[[#This Row],[Remit]]<>""),tblLines[[#This Row],[Stale_prepay]]=0),"as-at date (no fund receipt recorded)","as-at date (nothing applied to this payday)"))),"") -> fund receipt | AR3: =IF((tblLines[[#This Row],[Exposed]]=1),IF(AND(tblLines[[#This Row],[Settled]]<>"",tblLines[[#This Row],[Stale_prepay]]=0,(tblLines[[#This Row],[Receipt_credit]]>=tblLines[[#This Row],[sg_amount]])),tblLines[[#This Row],[Settled]],Summary!$B$2),"") -> 46238 | AS3: =IF((tblLines[[#This Row],[Exposed]]=1),MIN(IF(Summary!$B$3="",DATE(2030,12,31),Summary!$B$3-1),IF(AND(tblLines[[#This Row],[Settled]]<>"",tblLines[[#This Row],[Stale_prepay]]=0,(tblLines[[#This Row],[Receipt_credit]]>=tblLines[[#This Row],[sg_amount]]),tblLines[[#This Row],[Final_shortfall]]=0),tblLines[[#This Row],[Settled]],Summary!$B$2)),"") -> 46238 | AT3: =IF((tblLines[[#This Row],[Exposed]]=1),IF(tblLines[[#This Row],[Past_horizon]]=1,"",MAX(tblLines[[#This Row],[Outstanding_to]]-tblLines[[#This Row],[Final_due]],0)),"") -> 15 | AU3: =IF((tblLines[[#This Row],[Exposed]]=1),IF(tblLines[[#This Row],[NEC_end]]>tblLines[[#This Row],[Final_due]],tblLines[[#This Row],[Base_shortfall]]*(EXP(SUMPRODUCT((((((tblLines[[#This Row],[NEC_end]]+tblGic[to]-ABS(tblLines[[#This Row],[NEC_end]]-tblGic[to]))/2)-(((tblLines[[#This Row],[Final_due]]+1)+tblGic[from]+ABS((tblLines[[#This Row],[Final_due]]+1)-tblGic[from]))/2)+1)>0)*(((tblLines[[#This Row],[NEC_end]]+tblGic[to]-ABS(tblLines[[#This Row],[NEC_end]]-tblGic[to]))/2)-(((tblLines[[#This Row],[Final_due]]+1)+tblGic[from]+ABS((tblLines[[#This Row],[Final_due]]+1)-tblGic[from]))/2)+1))*LN(1+tblGic[annual_pct]/100/tblGic[divisor])))-1),0),"") -> 2.5420883 | AV3: =IF((tblLines[[#This Row],[Exposed]]=1),IF(tblLines[[#This Row],[NEC_end]]>Summary!$B$7,1,0),"") -> 0 | AW3: =IF((tblLines[[#This Row],[Exposed]]=1),ROUND(tblLines[[#This Row],[Final_shortfall]],2),"") -> 0 | AX3: =IF((tblLines[[#This Row],[Exposed]]=1),ROUND(tblLines[[#This Row],[NEC]],2),"") -> 2.54 | AY3: =IF((tblLines[[#This Row],[Exposed]]=1),0,"") -> 0 | AZ3: =IF((tblLines[[#This Row],[Exposed]]=1),ROUND(0.6*(tblLines[[#This Row],[Final_shortfall]]+tblLines[[#This Row],[NEC]]),2),"") -> 1.53 | BA3: =IF((tblLines[[#This Row],[Exposed]]=1),tblLines[[#This Row],[Shortfall_r]]+tblLines[[#This Row],[NEC_r]]+tblLines[[#This Row],[Uplift_best]],"") -> 2.54 | BB3: =IF((tblLines[[#This Row],[Exposed]]=1),tblLines[[#This Row],[Shortfall_r]]+tblLines[[#This Row],[NEC_r]]+tblLines[[#This Row],[Uplift_worst]],"") -> 4.07 | BC3: =IF(AND(tblLines[[#This Row],[Flag_db]]<>1,ISNUMBER(tblLines[[#This Row],[sg_amount]]),tblLines[[#This Row],[sg_amount]]>0,tblLines[[#This Row],[Cap]]>0,OR(ISNUMBER(tblLines[[#This Row],[fund_received_date]]),ISNUMBER(tblLines[[#This Row],[remitted_date]])),IF(ISNUMBER(tblLines[[#This Row],[fund_received_date]]),tblLines[[#This Row],[fund_received_date]],tblLines[[#This Row],[remitted_date]])<=DATE(2026,7,28)),1,0) -> 0 | BD3: =IF(tblLines[[#This Row],[Settled]]<>"",1,0) -> 1 | BE3: =IF(AND(tblLines[[#This Row],[Verdict]]<>"",tblLines[[#This Row],[Verdict]]<>"SKIPPED",ISNUMBER(tblLines[[#This Row],[sg_amount]]),tblLines[[#This Row],[sg_amount]]>0),1,0) -> 1 | BF3: =IF(COUNTIFS(tblLines[employee_id],tblLines[[#This Row],[employee_id]],tblLines[payment_date],tblLines[[#This Row],[payment_date]],tblLines[sg_amount],tblLines[[#This Row],[sg_amount]],tblLines[remitted_date],tblLines[[#This Row],[remitted_date]]&"",tblLines[fund_received_date],tblLines[[#This Row],[fund_received_date]]&"")>1,1,0) -> 0
A4: EMP003 | B4: 46212 | C4: 318 | D4: 46218 | H4: no | I4: no | K4: no | L4: =IF(OR(LOWER(TRIM(tblLines[[#This Row],[defined_benefit]]&""))={"1","t","true","y","yes"}),1,IF(OR(LOWER(TRIM(tblLines[[#This Row],[defined_benefit]]&""))={"","0","f","false","n","no"}),0,"")) -> 0 | M4: =IF(OR(LOWER(TRIM(tblLines[[#This Row],[out_of_cycle]]&""))={"1","t","true","y","yes"}),1,IF(OR(LOWER(TRIM(tblLines[[#This Row],[out_of_cycle]]&""))={"","0","f","false","n","no"}),0,"")) -> 0 | N4: =IF(OR(LOWER(TRIM(tblLines[[#This Row],[first_contribution_to_fund]]&""))={"1","t","true","y","yes"}),1,IF(OR(LOWER(TRIM(tblLines[[#This Row],[first_contribution_to_fund]]&""))={"","0","f","false","n","no"}),0,"")) -> 0 | O4: =TRIM(IF(OR(AND(tblLines[[#This Row],[payment_date]]<>"",NOT(ISNUMBER(tblLines[[#This Row],[payment_date]]))),AND(tblLines[[#This Row],[remitted_date]]<>"",NOT(ISNUMBER(tblLines[[#This Row],[remitted_date]]))),AND(tblLines[[#This Row],[fund_received_date]]<>"",NOT(ISNUMBER(tblLines[[#This Row],[fund_received_date]]))),AND(tblLines[[#This Row],[next_standard_payday]]<>"",NOT(ISNUMBER(tblLines[[#This Row],[next_standard_payday]])))),"date ","")&IF(NOT(ISNUMBER(tblLines[[#This Row],[payment_date]])),"payment_date ","")&IF(AND(ISNUMBER(tblLines[[#This Row],[payment_date]]),tblLines[[#This Row],[payment_date]]<DATE(2026,7,1)),"pre-1-Jul-2026 ","")&IF(OR(AND(tblLines[[#This Row],[sg_amount]]<>"",OR(NOT(ISNUMBER(tblLines[[#This Row],[sg_amount]])),tblLines[[#This Row],[sg_amount]]<0)),AND(tblLines[[#This Row],[remitted_amount]]<>"",OR(NOT(ISNUMBER(tblLines[[#This Row],[remitted_amount]])),tblLines[[#This Row],[remitted_amount]]<0)),AND(tblLines[[#This Row],[matched_amount]]<>"",OR(NOT(ISNUMBER(tblLines[[#This Row],[matched_amount]])),tblLines[[#This Row],[matched_amount]]<0))),"amount ","")&IF(NOT(ISNUMBER(tblLines[[#This Row],[sg_amount]])),"sg_amount ","")&IF(OR(tblLines[[#This Row],[Flag_ftf]]="",tblLines[[#This Row],[Flag_ooc]]="",tblLines[[#This Row],[Flag_db]]=""),"yes/no ","")&IF(AND(ISNUMBER(tblLines[[#This Row],[remitted_amount]]),ISNUMBER(tblLines[[#This Row],[sg_amount]]),tblLines[[#This Row],[remitted_amount]]>tblLines[[#This Row],[sg_amount]]),"remitted_amount>sg ","")&IF(AND(ISNUMBER(tblLines[[#This Row],[remitted_amount]]),NOT(ISNUMBER(tblLines[[#This Row],[remitted_date]]))),"remitted_amount-needs-date ","")&IF(AND(ISNUMBER(tblLines[[#This Row],[matched_amount]]),ISNUMBER(tblLines[[#This Row],[sg_amount]]),tblLines[[#This Row],[matched_amount]]>tblLines[[#This Row],[sg_amount]]),"matched_amount>sg ","")&IF(AND(ISNUMBER(tblLines[[#This Row],[matched_amount]]),ISNUMBER(tblLines[[#This Row],[remitted_amount]]),tblLines[[#This Row],[remitted_amount]]>tblLines[[#This Row],[matched_amount]]),"remitted_amount>matched ","")&IF(AND(ISNUMBER(tblLines[[#This Row],[matched_amount]]),ISNUMBER(tblLines[[#This Row],[sg_amount]]),tblLines[[#This Row],[matched_amount]]<tblLines[[#This Row],[sg_amount]],ISNUMBER(tblLines[[#This Row],[remitted_date]]),NOT(ISNUMBER(tblLines[[#This Row],[remitted_amount]]))),"partial-match-needs-remitted_amount ","")&IF(AND(ISNUMBER(tblLines[[#This Row],[fund_received_date]]),ISNUMBER(tblLines[[#This Row],[remitted_date]]),tblLines[[#This Row],[fund_received_date]]<tblLines[[#This Row],[remitted_date]]),"receipt-before-remittance ","")&IF(AND(tblLines[[#This Row],[Flag_ooc]]=1,NOT(ISNUMBER(tblLines[[#This Row],[next_standard_payday]]))),"out_of_cycle-needs-next_standard_payday ","")&IF(AND(tblLines[[#This Row],[Flag_ooc]]=1,ISNUMBER(tblLines[[#This Row],[next_standard_payday]]),ISNUMBER(tblLines[[#This Row],[payment_date]]),tblLines[[#This Row],[next_standard_payday]]<=tblLines[[#This Row],[payment_date]]),"next_standard_payday-not-after-payday ","")) | P4: =IF(OR(_xlfn.ISFORMULA(tblLines[[#This Row],[employee_id]]),_xlfn.ISFORMULA(tblLines[[#This Row],[payment_date]]),_xlfn.ISFORMULA(tblLines[[#This Row],[sg_amount]]),_xlfn.ISFORMULA(tblLines[[#This Row],[remitted_date]]),_xlfn.ISFORMULA(tblLines[[#This Row],[remitted_amount]]),_xlfn.ISFORMULA(tblLines[[#This Row],[matched_amount]]),_xlfn.ISFORMULA(tblLines[[#This Row],[fund_received_date]]),_xlfn.ISFORMULA(tblLines[[#This Row],[first_contribution_to_fund]]),_xlfn.ISFORMULA(tblLines[[#This Row],[out_of_cycle]]),_xlfn.ISFORMULA(tblLines[[#This Row],[next_standard_payday]]),_xlfn.ISFORMULA(tblLines[[#This Row],[defined_benefit]])),1,0) -> 0 | Q4: =IF(ISNUMBER(tblLines[[#This Row],[matched_amount]]),tblLines[[#This Row],[matched_amount]],IF(ISNUMBER(tblLines[[#This Row],[remitted_amount]]),tblLines[[#This Row],[remitted_amount]],tblLines[[#This Row],[sg_amount]])) -> 318 | R4: =IF(AND(tblLines[[#This Row],[Flag_ooc]]=1,ISNUMBER(tblLines[[#This Row],[next_standard_payday]])),WORKDAY.INTL(tblLines[[#This Row],[next_standard_payday]],7,1,tblHolidays[date]),"") | S4: =IF(tblLines[[#This Row],[Flag_ftf]]=1,WORKDAY.INTL(tblLines[[#This Row],[payment_date]],20,1,tblHolidays[date]),"") | T4: =IF(OR(tblLines[[#This Row],[Flag_db]]=1,NOT(ISNUMBER(tblLines[[#This Row],[payment_date]]))),"",IF(OR(tblLines[[#This Row],[Flag_ooc]]=1,tblLines[[#This Row],[Flag_ftf]]=1),MAX(tblLines[[#This Row],[Due_ooc]],tblLines[[#This Row],[Due_ftf]]),WORKDAY.INTL(tblLines[[#This Row],[payment_date]],7,1,tblHolidays[date]))) -> 46223 | U4: =IF(tblLines[[#This Row],[Flag_db]]=1,"SKIP_DB",IF(tblLines[[#This Row],[Flag_ooc]]=1,IF(AND(tblLines[[#This Row],[Flag_ftf]]=1,tblLines[[#This Row],[Due_ftf]]>tblLines[[#This Row],[Due_ooc]]),"EXTENDED_20BD","OUT_OF_CYCLE"),IF(tblLines[[#This Row],[Flag_ftf]]=1,"EXTENDED_20BD","USUAL_7BD"))) -> USUAL_7BD | V4: =IF(ISNUMBER(tblLines[[#This Row],[payment_date]]),EDATE(tblLines[[#This Row],[payment_date]]-1,-12)+1,"") -> 45847 | W4: =IF(AND(ISNUMBER(tblLines[[#This Row],[fund_received_date]]),tblLines[[#This Row],[fund_received_date]]<=Summary!$B$2),tblLines[[#This Row],[fund_received_date]],"") | X4: =IF(AND(ISNUMBER(tblLines[[#This Row],[remitted_date]]),tblLines[[#This Row],[remitted_date]]<=Summary!$B$2),tblLines[[#This Row],[remitted_date]],"") -> 46218 | Y4: =IF(tblLines[[#This Row],[Settled]]<>"",MIN(ROUND(tblLines[[#This Row],[Cap]],2),ROUND(tblLines[[#This Row],[sg_amount]],2)),0) -> 0 | Z4: =IF(ISNUMBER(tblLines[[#This Row],[remitted_amount]]),IF(tblLines[[#This Row],[Remit]]<>"",MIN(ROUND(tblLines[[#This Row],[remitted_amount]],2),ROUND(tblLines[[#This Row],[sg_amount]],2)),0),IF(tblLines[[#This Row],[Remit]]<>"",ROUND(tblLines[[#This Row],[sg_amount]],2),0)) -> 318 | AA4: =IF(OR(tblLines[[#This Row],[Own_due]]="",tblLines[[#This Row],[sg_amount]]<=0,tblLines[[#This Row],[Flag_db]]=1,tblLines[[#This Row],[Cap]]<=0),"impossible",IF(ISNUMBER(tblLines[[#This Row],[fund_received_date]]),IF(tblLines[[#This Row],[fund_received_date]]<tblLines[[#This Row],[Earliest_prepay]],"impossible",IF(tblLines[[#This Row],[fund_received_date]]<=Summary!$B$2,IF(OR(tblLines[[#This Row],[fund_received_date]]<tblLines[[#This Row],[payment_date]],tblLines[[#This Row],[fund_received_date]]<=tblLines[[#This Row],[Own_due]]),"confirmed",IF(tblLines[[#This Row],[fund_received_date]]>tblLines[[#This Row],[Own_due]],"impossible","possible")),IF(tblLines[[#This Row],[fund_received_date]]<=tblLines[[#This Row],[Own_due]],"possible","impossible"))),IF(AND(ISNUMBER(tblLines[[#This Row],[remitted_date]]),tblLines[[#This Row],[remitted_date]]>tblLines[[#This Row],[Own_due]]),"impossible","possible"))) -> possible | AB4: =IF(OR(tblLines[[#This Row],[Flag_db]]=1,tblLines[[#This Row],[Own_due]]=""),"",_xlfn.MAXIFS(tblLines[Own_due],tblLines[employee_id],tblLines[[#This Row],[employee_id]],tblLines[payment_date],"<"&tblLines[[#This Row],[payment_date]],tblLines[Evidence_own],"confirmed")) -> 0 | AC4: =IF(OR(tblLines[[#This Row],[Flag_db]]=1,tblLines[[#This Row],[Own_due]]=""),"",_xlfn.MAXIFS(tblLines[Own_due],tblLines[employee_id],tblLines[[#This Row],[employee_id]],tblLines[payment_date],"<"&tblLines[[#This Row],[payment_date]],tblLines[Evidence_own],"<>impossible")) -> 0 | AD4: =IF(tblLines[[#This Row],[Own_due]]="","",IF(AND(ISNUMBER(tblLines[[#This Row],[Confirmed_latest]]),tblLines[[#This Row],[Confirmed_latest]]>tblLines[[#This Row],[Own_due]]),tblLines[[#This Row],[Confirmed_latest]],tblLines[[#This Row],[Own_due]])) -> 46223 | AE4: =IF(tblLines[[#This Row],[Own_due]]="",tblLines[[#This Row],[Own_pathway]],IF(AND(ISNUMBER(tblLines[[#This Row],[Confirmed_latest]]),tblLines[[#This Row],[Confirmed_latest]]>tblLines[[#This Row],[Own_due]]),"ITEM4_ALIGNED",tblLines[[#This Row],[Own_pathway]])) -> USUAL_7BD | AF4: =IF(tblLines[[#This Row],[Final_due]]="","",IF(AND(ISNUMBER(tblLines[[#This Row],[Possible_latest]]),tblLines[[#This Row],[Possible_latest]]>tblLines[[#This Row],[Final_due]]),tblLines[[#This Row],[Possible_latest]],"")) | AG4: =IF(tblLines[[#This Row],[Final_due]]="","",IF((tblLines[[#This Row],[Final_due]]>Summary!$B$6),1,0)) -> 0 | AH4: =IF(tblLines[[#This Row],[Flag_db]]=1,"DB",IF(tblLines[[#This Row],[Final_due]]="","",IF(tblLines[[#This Row],[sg_amount]]<=0,"NIL",IF(tblLines[[#This Row],[Settled]]<>"",IF(tblLines[[#This Row],[Settled]]<tblLines[[#This Row],[payment_date]],IF(tblLines[[#This Row],[Settled]]>=tblLines[[#This Row],[Earliest_prepay]],IF((tblLines[[#This Row],[Receipt_credit]]>=tblLines[[#This Row],[sg_amount]]),"A1",IF(tblLines[[#This Row],[Final_due]]>=Summary!$B$2,"A2",IF(OR((tblLines[[#This Row],[Final_due]]>Summary!$B$6),AND((tblLines[[#This Row],[Possible_item4]]<>""),Summary!$B$2<=tblLines[[#This Row],[Possible_item4]])),"A3","A4"))),IF(tblLines[[#This Row],[Final_due]]>=Summary!$B$2,"S1",IF(OR((tblLines[[#This Row],[Final_due]]>Summary!$B$6),AND((tblLines[[#This Row],[Possible_item4]]<>""),Summary!$B$2<=tblLines[[#This Row],[Possible_item4]])),"S2","S3"))),IF(AND((tblLines[[#This Row],[Possible_item4]]<>""),tblLines[[#This Row],[Final_due]]<tblLines[[#This Row],[Settled]],tblLines[[#This Row],[Settled]]<=tblLines[[#This Row],[Possible_item4]]),IF((tblLines[[#This Row],[Receipt_credit]]>=tblLines[[#This Row],[sg_amount]]),"B1",IF(Summary!$B$2<=tblLines[[#This Row],[Possible_item4]],"B2","B3")),IF(AND((tblLines[[#This Row],[Final_due]]>Summary!$B$6),tblLines[[#This Row],[Settled]]>tblLines[[#This Row],[Final_due]]),IF((tblLines[[#This Row],[Receipt_credit]]>=tblLines[[#This Row],[sg_amount]]),"C1","C2"),IF(tblLines[[#This Row],[Settled]]<=tblLines[[#This Row],[Final_due]],IF((tblLines[[#This Row],[Receipt_credit]]>=tblLines[[#This Row],[sg_amount]]),"D1",IF(OR((tblLines[[#This Row],[Final_due]]>Summary!$B$6),AND((tblLines[[#This Row],[Possible_item4]]<>""),Summary!$B$2<=tblLines[[#This Row],[Possible_item4]])),"D2",IF(tblLines[[#This Row],[Final_due]]<Summary!$B$2,"D3","D4"))),"E")))),IF(AND(tblLines[[#This Row],[Remit]]<>"",tblLines[[#This Row],[sg_amount]]-tblLines[[#This Row],[Credit]]<=0),IF(AND((tblLines[[#This Row],[Possible_item4]]<>""),tblLines[[#This Row],[Final_due]]<tblLines[[#This Row],[Remit]],tblLines[[#This Row],[Remit]]<=tblLines[[#This Row],[Possible_item4]]),"R1",IF(AND((tblLines[[#This Row],[Final_due]]>Summary!$B$6),tblLines[[#This Row],[Remit]]>tblLines[[#This Row],[Final_due]]),"R2",IF(tblLines[[#This Row],[Remit]]<=tblLines[[#This Row],[Final_due]],"R3","R4"))),IF(tblLines[[#This Row],[Final_due]]<Summary!$B$2,IF(OR((tblLines[[#This Row],[Final_due]]>Summary!$B$6),AND((tblLines[[#This Row],[Possible_item4]]<>""),Summary!$B$2<=tblLines[[#This Row],[Possible_item4]])),"N1","N2"),"N3")))))) -> R3 | AI4: =IF(tblLines[[#This Row],[Branch]]="","",INDEX(tblCodes[verdict],MATCH(tblLines[[#This Row],[Branch]],tblCodes[code],0))) -> AT_RISK | AJ4: =IF(tblLines[[#This Row],[Branch]]="","",T(INDEX(tblCodes[unassessable],MATCH(tblLines[[#This Row],[Branch]],tblCodes[code],0)))) | AK4: =IF(tblLines[[#This Row],[Branch]]="",0,INDEX(tblCodes[exposed],MATCH(tblLines[[#This Row],[Branch]],tblCodes[code],0))) -> 0 | AL4: =IF(tblLines[[#This Row],[Branch]]="",0,INDEX(tblCodes[stale],MATCH(tblLines[[#This Row],[Branch]],tblCodes[code],0))) -> 0 | AM4: =IF(tblLines[[#This Row],[Branch]]="",0,INDEX(tblCodes[otrc],MATCH(tblLines[[#This Row],[Branch]],tblCodes[code],0))*tblLines[[#This Row],[Receipt_credit]]) -> 0 | AN4: =IF((tblLines[[#This Row],[Exposed]]=1),MAX(ROUND(tblLines[[#This Row],[sg_amount]],2)-tblLines[[#This Row],[OTRC]],0),"") | AO4: =IF((tblLines[[#This Row],[Exposed]]=1),IF(AND(tblLines[[#This Row],[Settled]]<>"",tblLines[[#This Row],[Stale_prepay]]=0,tblLines[[#This Row],[Settled]]>tblLines[[#This Row],[Final_due]],OR(Summary!$B$3="",tblLines[[#This Row],[Settled]]<Summary!$B$3)),MIN(tblLines[[#This Row],[Receipt_credit]],tblLines[[#This Row],[Base_shortfall]]),0),"") | AP4: =IF((tblLines[[#This Row],[Exposed]]=1),MAX(tblLines[[#This Row],[Base_shortfall]]-tblLines[[#This Row],[Offset_s18D]],0),"") | AQ4: =IF((tblLines[[#This Row],[Exposed]]=1),IF(AND(tblLines[[#This Row],[Settled]]<>"",tblLines[[#This Row],[Stale_prepay]]=0,(tblLines[[#This Row],[Receipt_credit]]>=tblLines[[#This Row],[sg_amount]])),"fund receipt",IF(AND(tblLines[[#This Row],[Settled]]<>"",tblLines[[#This Row],[Stale_prepay]]=0),"as-at date (shortfall remains after part receipt)",IF(AND(OR(tblLines[[#This Row],[Settled]]<>"",tblLines[[#This Row],[Remit]]<>""),tblLines[[#This Row],[Stale_prepay]]=0),"as-at date (no fund receipt recorded)","as-at date (nothing applied to this payday)"))),"") | AR4: =IF((tblLines[[#This Row],[Exposed]]=1),IF(AND(tblLines[[#This Row],[Settled]]<>"",tblLines[[#This Row],[Stale_prepay]]=0,(tblLines[[#This Row],[Receipt_credit]]>=tblLines[[#This Row],[sg_amount]])),tblLines[[#This Row],[Settled]],Summary!$B$2),"") | AS4: =IF((tblLines[[#This Row],[Exposed]]=1),MIN(IF(Summary!$B$3="",DATE(2030,12,31),Summary!$B$3-1),IF(AND(tblLines[[#This Row],[Settled]]<>"",tblLines[[#This Row],[Stale_prepay]]=0,(tblLines[[#This Row],[Receipt_credit]]>=tblLines[[#This Row],[sg_amount]]),tblLines[[#This Row],[Final_shortfall]]=0),tblLines[[#This Row],[Settled]],Summary!$B$2)),"") | AT4: =IF((tblLines[[#This Row],[Exposed]]=1),IF(tblLines[[#This Row],[Past_horizon]]=1,"",MAX(tblLines[[#This Row],[Outstanding_to]]-tblLines[[#This Row],[Final_due]],0)),"") | AU4: =IF((tblLines[[#This Row],[Exposed]]=1),IF(tblLines[[#This Row],[NEC_end]]>tblLines[[#This Row],[Final_due]],tblLines[[#This Row],[Base_shortfall]]*(EXP(SUMPRODUCT((((((tblLines[[#This Row],[NEC_end]]+tblGic[to]-ABS(tblLines[[#This Row],[NEC_end]]-tblGic[to]))/2)-(((tblLines[[#This Row],[Final_due]]+1)+tblGic[from]+ABS((tblLines[[#This Row],[Final_due]]+1)-tblGic[from]))/2)+1)>0)*(((tblLines[[#This Row],[NEC_end]]+tblGic[to]-ABS(tblLines[[#This Row],[NEC_end]]-tblGic[to]))/2)-(((tblLines[[#This Row],[Final_due]]+1)+tblGic[from]+ABS((tblLines[[#This Row],[Final_due]]+1)-tblGic[from]))/2)+1))*LN(1+tblGic[annual_pct]/100/tblGic[divisor])))-1),0),"") | AV4: =IF((tblLines[[#This Row],[Exposed]]=1),IF(tblLines[[#This Row],[NEC_end]]>Summary!$B$7,1,0),"") | AW4: =IF((tblLines[[#This Row],[Exposed]]=1),ROUND(tblLines[[#This Row],[Final_shortfall]],2),"") | AX4: =IF((tblLines[[#This Row],[Exposed]]=1),ROUND(tblLines[[#This Row],[NEC]],2),"") | AY4: =IF((tblLines[[#This Row],[Exposed]]=1),0,"") | AZ4: =IF((tblLines[[#This Row],[Exposed]]=1),ROUND(0.6*(tblLines[[#This Row],[Final_shortfall]]+tblLines[[#This Row],[NEC]]),2),"") | BA4: =IF((tblLines[[#This Row],[Exposed]]=1),tblLines[[#This Row],[Shortfall_r]]+tblLines[[#This Row],[NEC_r]]+tblLines[[#This Row],[Uplift_best]],"") | BB4: =IF((tblLines[[#This Row],[Exposed]]=1),tblLines[[#This Row],[Shortfall_r]]+tblLines[[#This Row],[NEC_r]]+tblLines[[#This Row],[Uplift_worst]],"") | BC4: =IF(AND(tblLines[[#This Row],[Flag_db]]<>1,ISNUMBER(tblLines[[#This Row],[sg_amount]]),tblLines[[#This Row],[sg_amount]]>0,tblLines[[#This Row],[Cap]]>0,OR(ISNUMBER(tblLines[[#This Row],[fund_received_date]]),ISNUMBER(tblLines[[#This Row],[remitted_date]])),IF(ISNUMBER(tblLines[[#This Row],[fund_received_date]]),tblLines[[#This Row],[fund_received_date]],tblLines[[#This Row],[remitted_date]])<=DATE(2026,7,28)),1,0) -> 1 | BD4: =IF(tblLines[[#This Row],[Settled]]<>"",1,0) -> 0 | BE4: =IF(AND(tblLines[[#This Row],[Verdict]]<>"",tblLines[[#This Row],[Verdict]]<>"SKIPPED",ISNUMBER(tblLines[[#This Row],[sg_amount]]),tblLines[[#This Row],[sg_amount]]>0),1,0) -> 1 | BF4: =IF(COUNTIFS(tblLines[employee_id],tblLines[[#This Row],[employee_id]],tblLines[payment_date],tblLines[[#This Row],[payment_date]],tblLines[sg_amount],tblLines[[#This Row],[sg_amount]],tblLines[remitted_date],tblLines[[#This Row],[remitted_date]]&"",tblLines[fund_received_date],tblLines[[#This Row],[fund_received_date]]&"")>1,1,0) -> 0
